#VRML_SIM R2023b utf8
# license: Creative Commons Attribution 4.0 International License.
# license url: https://creativecommons.org/licenses/by/4.0/legalcode
# documentation url: https://webots.cloud/run?url=https://github.com/cyberbotics/webots/blob/released/projects/objects/trees/protos/Cypress.proto
# keywords: exterior/tree
# A cypress tree with optional boundingObject.
# template language: javascript


PROTO M100 [
  field SFVec3f    translation         0 0 0.15
  field SFRotation rotation            1 0 0 0
  field SFString   name                "M100"
  field SFString   model               "M100"
  field SFNode     physics             Physics {
                                          density -1
                                          mass 2.70703
                                          centerOfMass [
                                            0 0 0
                                          ]
                                          inertiaMatrix [
                                            0.0341171 0.0363089 0.0627386
                                            0 0 0
                                          ]
                                        }
  field MFColor    recognitionColors   1 0 0
  field SFString   controller          ""
  field MFString   controllerArgs      []
  field SFString   customData          ""
  field SFBool     supervisor          FALSE
  field SFBool     synchronization     TRUE
  field MFNode     bodySlot            [ DEF GPS GPS {
                                         }
                                         DEF GYRO Gyro {
                                         }
                                         DEF INERTIAL_UNIT InertialUnit {
                                         }
                                         DEF ACCELEROMETER Accelerometer {
                                         }
                                         DEF RPLIDRA2 RpLidarA2 {
                                         }
                                         DEF EMITTER Emitter{
                                           type "serial"
                                           channel 0
                                         }
                                         DEF RECEIVER Receiver{
                                           type "serial"
                                           channel 1
                                         }
                                         DEF DISPLAY Display{
                                         }]
  field MFNode     cameraSlot          [ Camera { width 320 height 240 } ] # Extends the robot with a Camera.
  field SFFloat    rollAngle           0
  field SFFloat    pitchAngle          0
  field SFFloat    yawAngle            0
]
{
  Robot {
    translation IS translation
    rotation IS rotation
    name IS name
    model IS model
    physics IS physics
    recognitionColors IS recognitionColors
    controller IS controller
    controllerArgs IS controllerArgs
    supervisor IS supervisor
    customData IS customData
    synchronization IS synchronization
    boundingObject Box {
      size 0.806 0.806 0.366
    }
    children [
      Group {
        children IS bodySlot
      }
      LED {
        translation -0.076933 0 -0.022
        rotation 1 0 0 1.5707996938995747
        children [
          Shape {
            appearance PBRAppearance {
              roughness 1
              metalness 0
              emissiveIntensity 100
            }
            geometry Box {
              size 0.01 0.015 0.008
            }
          }
        ]
        color [
          0 1 0
        ]
      }
      DEF CAMERA_YAW HingeJoint {
      jointParameters HingeJointParameters {
        position IS yawAngle
        axis 0 0 1
        anchor 0.13 -0.00469654 -0.013
        dampingConstant 0.001
      }
      device [
        RotationalMotor {
          name "camera yaw"
          minPosition -1.7
          maxPosition 1.7
          maxVelocity 35
        }
        PositionSensor {
          name "camera yaw sensor"
        }
      ]
      endPoint Solid {
        translation 0.13 -0.00469654 -0.013
        rotation 0 0 1 0
        children [
          Shape {
            appearance PBRAppearance {
              roughness 0.5
            }
            geometry Mesh {
              url "https://raw.githubusercontent.com/cyberbotics/webots/R2023b/projects/robots/dji/mavic/protos/Mavic2Pro/meshes/camera_yaw.obj"
            }
          }
          DEF CAMERA_PITCH HingeJoint {
            jointParameters HingeJointParameters {
              position IS pitchAngle
              axis 0 1 0
              anchor 0.000625212 -0.00530346 -0.0207448
              dampingConstant 0.001
            }
            device [
              RotationalMotor {
                name "camera pitch"
                minPosition -0.5
                maxPosition 1.7
                maxVelocity 35
              }
              PositionSensor {
                name "camera pitch sensor"
              }
            ]
            endPoint Solid {
              translation 0.000625212 -0.00530346 -0.0207448
              children [
                Shape {
                  appearance PBRAppearance {
                    roughness 0.5
                  }
                  geometry Mesh {
                    url "https://raw.githubusercontent.com/cyberbotics/webots/R2023b/projects/robots/dji/mavic/protos/Mavic2Pro/meshes/camera_pitch.obj"
                  }
                }
                DEF CAMERA_ROLL HingeJoint {
                  jointParameters HingeJointParameters {
                    position IS rollAngle
                    anchor 0.00754686 0.0160388 -0.00586401
                    dampingConstant 0.001
                  }
                  device [
                    RotationalMotor {
                      name "camera roll"
                      minPosition -0.5
                      maxPosition 0.5
                      maxVelocity 35
                    }
                    PositionSensor {
                      name "camera roll sensor"
                    }
                  ]
                  endPoint Solid {
                    translation 0.00754686 0.0160388 -0.00586401
                    rotation 1 0 0 0
                    children [
                      Shape {
                        appearance PBRAppearance {
                          roughness 0.5
                        }
                        geometry Mesh {
                          url "https://raw.githubusercontent.com/cyberbotics/webots/R2023b/projects/robots/dji/mavic/protos/Mavic2Pro/meshes/camera_chassis.obj"
                        }
                      }
                      Shape {
                        appearance PBRAppearance {
                          baseColor 0.523146 0.8 0.627785
                          transparency 0.9
                          roughness 0.5
                          metalness 0
                        }
                        geometry Mesh {
                          url "https://raw.githubusercontent.com/cyberbotics/webots/R2023b/projects/robots/dji/mavic/protos/Mavic2Pro/meshes/camera_lens.obj"
                        }
                      }
                      DEF CAMERA_SLOT Pose {
                        children IS cameraSlot
                      }
                    ]
                    name "camera roll"
                    boundingObject Pose {
                      translation -0.00915058 -1.86265e-08 -0.000983764
                      children [
                        Box {
                          size 0.0236511 0.0205141 0.0225186
                        }
                      ]
                    }
                    physics Physics {
                      density -1
                      mass 0.0333
                    }
                  }
                }
              ]
              name "camera pitch"
              boundingObject Pose {
                translation -0.00248347 0.00776876 0.00183829
                children [
                  Box {
                    size 0.0239878 0.0349393 0.0314891
                  }
                ]
              }
              physics Physics {
                density -1
                mass 0.0333
              }
            }
          }
        ]
        name "camera yaw"
        boundingObject Pose {
          translation -1.86265e-09 -0.00304481 -0.0140589
          children [
            Box {
              size 0.0208626 0.0260333 0.0307844
            }
          ]
        }
        physics Physics {
          density -1
          mass 0.0333
        }
      }
    }
      DEF FRONT_RIGHT_PROP Transform {
        translation 0.22978 -0.22978 0.02305
        rotation 1 0 0 0
        children [
          Propeller {
            shaftAxis 0 0 1
            thrustConstants 2.55e-05 0
            torqueConstants 5.1e-07 0
            fastHelixThreshold 50
            device RotationalMotor {
              name "front_right_motor"
              acceleration -1
              maxVelocity 10000
              maxTorque 1e9
            }
            fastHelix Solid {
              children [
                Shape {
                  appearance PBRAppearance {
                    baseColor 0.5 0.5 0.5
                    baseColorMap ImageTexture {
                      url [
                        "textures/fast_helix.png"
                      ]
                    }
                    metalness 0
                  }
                  geometry Cylinder {
                    height 0.01
                    radius 0.14
                  }
                }
              ]
            }
            slowHelix Solid {
              children [
                Shape {
                  appearance PBRAppearance {
                    baseColor 0.5 0.5 0.5
                    roughness 0.8
                    metalness 0
                  }
                  geometry Mesh {
                    url [
                      "meshes/propeller_ccw.dae"
                    ]
                  }
                }
              ]
            }
          }
        ]
      }
      DEF FRONT_LEFT_PROP Transform {
        translation 0.22978 0.22978 0.02305
        rotation 1 0 0 0
        children [
          Propeller {
            shaftAxis 0 0 1
            thrustConstants -2.55e-05 0
            torqueConstants 5.1e-07 0
            fastHelixThreshold 50
            device RotationalMotor {
              name "front_left_motor"
              acceleration -1
              maxVelocity 10000
              maxTorque 1e9
            }
            fastHelix Solid {
              children [
                Shape {
                  appearance PBRAppearance {
                    baseColor 0.5 0.5 0.5
                    baseColorMap ImageTexture {
                      url [
                        "textures/fast_helix.png"
                      ]
                    }
                    metalness 0
                  }
                  geometry Cylinder {
                    height 0.01
                    radius 0.14
                  }
                }
              ]
            }
            slowHelix Solid {
              children [
                Shape {
                  appearance PBRAppearance {
                    baseColor 0.5 0.5 0.5
                    roughness 0.8
                    metalness 0
                  }
                  geometry Mesh {
                    url [
                      "meshes/propeller_cw.dae"
                    ]
                  }
                }
              ]
            }
          }
        ]
      }
      DEF REAR_LEFT_PROP Transform {
        translation -0.22978 0.22978 0.02305
        rotation 1 0 0 0
        children [
          Propeller {
            shaftAxis 0 0 1
            thrustConstants 2.55e-05 0
            torqueConstants 5.1e-07 0
            fastHelixThreshold 50
            device RotationalMotor {
              name "rear_left_motor"
              acceleration -1
              maxVelocity 10000
              maxTorque 1e9
            }
            fastHelix Solid {
              children [
                Shape {
                  appearance PBRAppearance {
                    baseColor 0.5 0.5 0.5
                    baseColorMap ImageTexture {
                      url [
                        "textures/fast_helix.png"
                      ]
                    }
                    metalness 0
                  }
                  geometry Cylinder {
                    height 0.01
                    radius 0.14
                  }
                }
              ]
            }
            slowHelix Solid {
              children [
                Shape {
                  appearance PBRAppearance {
                    baseColor 0.5 0.5 0.5
                    roughness 0.8
                    metalness 0
                  }
                  geometry Mesh {
                    url [
                      "meshes/propeller_ccw.dae"
                    ]
                  }
                }
              ]
            }
          }
        ]
      }
      DEF REAR_RIGHT_PROP Transform {
        translation -0.22978 -0.22978 0.02305
        rotation 1 0 0 0
        children [
          Propeller {
            shaftAxis 0 0 1
            thrustConstants -2.55e-05 0
            torqueConstants 5.1e-07 0
            fastHelixThreshold 50
            device RotationalMotor {
              name "rear_right_motor"
              acceleration -1
              maxVelocity 10000
              maxTorque 1e9
            }
            fastHelix Solid {
              children [
                Shape {
                  appearance PBRAppearance {
                    baseColor 0.5 0.5 0.5
                    baseColorMap ImageTexture {
                      url [
                        "textures/fast_helix.png"
                      ]
                    }
                    metalness 0
                  }
                  geometry Cylinder {
                    height 0.01
                    radius 0.14
                  }
                }
              ]
            }
            slowHelix Solid {
              children [
                Shape {
                  appearance PBRAppearance {
                    baseColor 0.5 0.5 0.5
                    roughness 0.8
                    metalness 0
                  }
                  geometry Mesh {
                    url [
                      "meshes/propeller_cw.dae"
                    ]
                  }
                }
              ]
            }
          }
        ]
      }
      DEF BODY Transform {
        rotation -0.5773509358554485 0.5773509358554485 0.5773489358556708 -2.094395307179586
        children [
          Shape {
            appearance PBRAppearance {
              baseColor 0 0 0
              roughness 1
              metalness 0
            }
            geometry Mesh {
              url [
                "meshes/M100.stl"
              ]
            }
          }
        ]
      }
    ]
  }
}