#VRML_SIM R2023b utf8
# license: Creative Commons Attribution 4.0 International License.
# license url: https://creativecommons.org/licenses/by/4.0/legalcode
# documentation url: https://webots.cloud/run?url=https://github.com/cyberbotics/webots/blob/released/projects/objects/trees/protos/Cypress.proto
# keywords: exterior/tree
# A cypress tree with optional boundingObject.
# template language: javascript

PROTO SimpleRobot [
  field SFVec3f    translation         0 0 0.15
  field SFRotation rotation            1 0 0 0
  field SFString   name                "SimpleRobot"
  field SFString   controller          ""
  field MFString   controllerArgs      []
  field SFString   customData          ""
  field SFNode     physics             Physics {
                                          density -1
                                          mass 2.70703
                                          centerOfMass [
                                            0 0 0
                                          ]
                                        }
  field MFNode     bodySlot            [ DEF GPS GPS {
                                         }
                                         DEF GYRO Gyro {
                                         }
                                         DEF INERTIAL_UNIT InertialUnit {
                                         }
                                         DEF ACCELEROMETER Accelerometer {
                                         }
                                         DEF RPLIDRA2 RpLidarA2 {
                                            translation -0.1 0 0
                                         }
                                         DEF EMITTER Emitter{
                                           type "serial"
                                           channel 0
                                         }
                                         DEF RECEIVER Receiver{
                                           type "serial"
                                           channel 1
                                         }]
  field MFNode     cameraSlot          [ Camera { width 320 height 240 } ] # Extends the robot with a Camera.
  field SFFloat    rollAngle           0
  field SFFloat    pitchAngle          0
  field SFFloat    yawAngle            0
]
{
    Robot {
        translation IS translation
        rotation IS rotation
        name IS name
        controller IS controller
        controllerArgs IS controllerArgs
        customData IS customData
        physics IS physics
        
        children [
            DEF CAMERA_YAW HingeJoint {
            jointParameters HingeJointParameters {
                position IS yawAngle
                axis 0 0 1
            }
            endPoint Solid {
                children [
                DEF CAMERA_PITCH HingeJoint {
                    jointParameters HingeJointParameters {
                        position IS pitchAngle
                        axis 0 1 0
                    }
                    endPoint Solid {
                    children [
                        DEF CAMERA_ROLL HingeJoint {
                        jointParameters HingeJointParameters {
                            position IS rollAngle
                            axis 1 0 0
                        }
                        endPoint Solid {
                            children [
                                DEF CAMERA_SLOT Pose {
                                    children IS cameraSlot
                                }
                            ]
                        }
                        }
                    ]
                    }
                }
                ]
            }
            }
            DEF bodySlot Group {
                children IS bodySlot
            }
        ]
        supervisor TRUE
    }
}